Workbook
Name a: #REF!
Name a: #REF!
Name a: #REF!
Name a: #REF!
Name a: #REF!
Name a: #REF!
Name a: #REF!
Name a: #REF!
Name a: #REF!
Name a: #REF!
Name aaa: #REF!
Name aaa: #REF!
Name aaa: #REF!
Name aaa: #REF!
Name aaa: #REF!
Name aaa: #REF!
Name aaa: #REF!
Name aaa: #REF!
Name aaa: #REF!
Name aaa: #REF!
Name AAAAA: #REF!
Name AAAAA: #REF!
Name AAAAA: #REF!
Name AAAAA: #REF!
Name AAAAA: #REF!
Name AAAAA: #REF!
Name AAAAA: #REF!
Name AAAAA: #REF!
Name AAAAA: #REF!
Name AAAAA: #REF!
Name AS: '[2]pw dept awd'!$A$120
Name asd: '[3]2002'!#REF!
Name asd: '[3]2002'!#REF!
Name asd: '[3]2002'!#REF!
Name asd: '[3]2002'!#REF!
Name asd: '[3]2002'!#REF!
Name asd: '[3]2002'!#REF!
Name asd: '[3]2002'!#REF!
Name asd: '[3]2002'!#REF!
Name asd: '[3]2002'!#REF!
Name asdf: '[4]2002'!#REF!
Name asdf: '[4]2002'!#REF!
Name asdf: '[4]2002'!#REF!
Name asdf: '[4]2002'!#REF!
Name asdf: '[4]2002'!#REF!
Name asdf: '[4]2002'!#REF!
Name asdf: '[4]2002'!#REF!
Name asdf: '[4]2002'!#REF!
Name asdf: '[4]2002'!#REF!
Name Asset: '[2]pw dept awd'!$A$153
Name Autorent: '[2]pw dept awd'!$A$223
Name AVERAGE: #REF!
Name AVERAGE: #REF!
Name AVERAGE: #REF!
Name AVERAGE: #REF!
Name AVERAGE: #REF!
Name AVERAGE: #REF!
Name AVERAGE: #REF!
Name AVERAGE: #REF!
Name AVERAGE: #REF!

Sheet Valterra Schdule
E2: VALTERRA PROJECT
E3: PLANNING ARRIVAL MATERIAL & DELIVERY PRODUCT
B5: Material Arrange | AT5: 2026
J6: January | AD6: February | AT6: March | BN6: April | CD6: May | CT6: June
J7: 1 | N7: 2 | R7: 3 | V7: 4 | Z7: 5 | AD7: 6 | AH7: 7 | AL7: 8 | AP7: 9 | AT7: 10 | AX7: 11 | BB7: 12 | BF7: 13 | BJ7: 14 | BN7: 15 | BR7: 16 | BV7: 17 | BZ7: 18 | CD7: 19 | CH7: 20 | CL7: 21 | CP7: 22 | CT7: 23 | CX7: 24 | DB7: 25 | DF7: 26
H8: Payment Material | I8: : | AY8: PO.9820, 9880, 9614 & 9915 | BL8: PO.9900,9926 & 9945
H9: Production Material (Supplier) | I9: :
F10: Delivery Material | H10: Air | I10: : | BD10: TPT 35W 2100
H11: Sea | I11: : | BD11: All Material Import | BP11: All Material Import
H12: Arrival Material | I12: :
H13: Incoming Check Material | I13: :
B14: No | C14: Detailed Project Order
C15: Order | E15: Type | G15: Qty
B16: 1 | C16: PO.9684 | D16: No.5 | E16: 82882-C | F16: 50 | G16: 1000
H17: Delivery Product : | BA17: 40 pcs
B18: 2 | C18: PO.9784 | D18: No.7 | E18: 82882-C | F18: 50 | G18: 1000
H19: Delivery Product : | BA19: 140 pcs | BT19: 360 pcs | BX19: 500 pcs
B20: 3 | C20: PO.9820 | D20: No.8 | E20: 1 Diode | F20: 35 | G20: 500
H21: Delivery Product : | AY21: 180 pcs
B22: 4 | C22: PO.9820 | D22: No.8 | E22: 1 Diode | F22: 35 | G22: 1500
H23: Delivery Product : | BA23: 540 pcs | BK23: 540 pcs | BO23: 420 PCS
B24: 5 | C24: PO.9820 | D24: No.8 | E24: 1 Diode | F24: 35 | G24: 2000
H25: Delivery Product : | BO25: 210 PCS | BS25: 1350 pcs | BW25: 440 PCS
B26: 6 | C26: PO.9880 | D26: No.9 | E26: 82882-C | F26: 50 | G26: 1000
H27: Delivery Product : | BY27: 1000 PCS
B28: 7 | C28: PO.9614 | D28: No.4 | F28: 110 | G28: 1500
H29: Delivery Product : | CC29: 1500 PCS
B30: 8 | C30: PO.9900 | D30: No.10 | E30: 82882-C | F30: 50 | G30: 1000
H31: Delivery Product : | CE31: 1000 PCS
B32: 9 | C32: PO.9915 | D32: No.11 | E32: 3 Diode | F32: 35 | G32: 2000
H33: Delivery Product : | CG33: 1000 PCS | CK33: 1000 PCS
B34: 10 | C34: PO.9926 | D34: No.12 | E34: 82882-C | F34: 50 | G34: 2000
H35: Delivery Product : | CL35: 1000 PCS | CP35: 1000 PCS
B36: 11 | C36: PO.9945 | D36: No.13 | E36: 82882-C | F36: 50 | G36: 1000
H37: Delivery Product : | CS37: 1000 PCS
B39: Note :

Sheet Valterra 26 Feb
H1: j
B5: Summary Delivery Schedule
B6: Customer : Valterra
B8: No. | C8: Company | E8: Panel | F8: Quantity | H8: Oct-25 | M8: Nov-25 | R8: Material 800 Pcs 295W | V8: Oct-25 | Z8: Oct-25
H9: 40 | I9: 41 | J9: 42 | K9: 42 | M9: 44 | N9: 45 | O9: 46 | P9: 47 | V9: 40 | W9: 41 | X9: 42 | Y9: 43 | Z9: 40 | AA9: 41 | AB9: 42 | AC9: 43
B10: 1 | C10: IconGreen | E10: 295W Panel | F10: 1500 | J10: 800 | K10: 800 | R10: Materials | T10: Detail | U10: Amount | X10: 800 | Y10: 700 | AB10: 800 | AC10: 700 | AE10: Due Date
J11: 24 Oct | K11: 24 Oct | R11: 295W Module | T11: PIB+Penalty | U11: 110000000 | X11: 24 Oct | Y11: 31 Oct | AB11: 24 Oct | AC11: 31 Oct | AE11: This week | AH11: 150 | AI11: 45961
M12: 540 | R12: Potting Gel | T12: PIB | U12: 500000 | Y12: 150 | AC12: 150 | AE12: 45957 | AH12: 300 | AI12: 45966
M13: Beg Nov | R13: Masterbox | T13: DP | U13: 15000000 | Y13: 31 Oct | AC13: 31 Oct | AE13: This week | AH13: 240 | AI13: 45968
B15: Feb 20th Schedule
A17: Internal No | B17: No. | C17: Company | D17: PO | E17: Panel | F17: PO Qty | G17: Month | H17: 46023 | M17: Feb-26 | Q17: Mar-26 | V17: 46113 | Z17: 46143 | AE17: Total
G18: Week | H18: 1 | I18: 2 | J18: 3 | K18: 4 | L18: 5 | M18: 6 | N18: 7 | O18: 8 | P18: 9 | Q18: 10 | R18: 11 | S18: 12 | T18: 13 | U18: 14 | V18: 15 | W18: 16 | X18: 17 | Y18: 18 | Z18: 19 | AA18: 20 | AB18: 21 | AC18: 22
A19: 5 | B19: 1 | C19: Valterra | D19: PO609684 | E19: 50W | F19: 1000 | G19: Qty | N19: 540 | O19: 420 | Q19: 40 | T19: Eid Al-Fitr Holiday | AG19: 5
G20: Date | N20: 14 Feb | O20: 21 Feb | Q20: TBD | AH20: 150 | AI20: 45961
A21: 6 | B21: 2 | D21: PO609804 | E21: 35W | F21: 1000 | G21: Qty | J21: 30 | K21: 90 | M21: 420 | N21: 450 | O21: 10 | AG21: 6
G22: Date | J22: 16 Jan | K22: 24 Jan | M22: 5 Feb | N22: 13 Feb | O22: 21 Feb
A23: 7 | B23: 3 | D23: PO609784 | E23: 50W | F23: 1000 | G23: Qty | S23: 500 | U23: 500 | AG23: 7
G24: Date | S24: TBD | U24: TBD
A25: 8 | B25: 4 | D25: PO609820 | E25: 35W | F25: 4000 | G25: Qty | O25: 320 | Q25: 180 | R25: 540 | S25: 720 | U25: 240 | V25: 1200 | W25: 800 | AG25: 8
G26: Date | O26: 21 Feb | Q26: TBD | R26: TBD | S26: TBD | U26: TBD | V26: TBD | W26: TBD
A27: 9 | B27: 5 | D27: PO609880 | E27: 50W | F27: 1000 | G27: Qty | U27: 500 | V27: 500 | AG27: 9
G28: Date | U28: TBD | V28: TBD
A29: 4 | B29: 6 | D29: PO609614 | E29: 110W | F29: 1500 | G29: Qty | W29: 900 | X29: 600 | AG29: 4
G30: Date | W30: TBD | X30: TBD
A31: 10 | B31: 7 | D31: PO609900 | E31: 50W | F31: 1000 | G31: Qty | X31: 1000 | AG31: 10
G32: Date | X32: TBD
A33: 11 | B33: 8 | D33: PO609915 | E33: 35W | F33: 2000 | G33: Qty | Y33: 2000 | AG33: 11
G34: Date | Y34: TBD
E35: 30W 3 Diode | F35: 5 | G35: Qty | Q35: 5
G36: Date | Q36: TBD
A37: 12 | B37: 9 | D37: PO609926 | E37: 50W | F37: 2000 | G37: Qty | Z37: 2000 | AG37: 12
G38: Date | Z38: TBD
A39: 13 | B39: 10 | D39: PO609945 | E39: 50W | F39: 1000 | G39: Qty | AA39: 1000 | AG39: 13
G40: Date | AA40: TBD
A41: 16900 | C41: Salary Payment | G41: Working Day | M41: Paid | N41: Paid | O41: 3 | P41: 5 | Q41: 6 | R41: 6 | S41: 2 | U41: 4 | V41: 4 | W41: 5 | X41: 6 | Y41: 6 | Z41: 6 | AA41: 5 | AE41: =SUM(O41:S41,U41:AC41) -> 58
G42: Cost | O42: =54000000/A41 -> 3195.2663 | P42: =(P41*'[7]Man Power'!$U$43)/'Valterra 26 Feb'!$A$41 -> 5520.8873 | Q42: =(Q41*'[7]Man Power'!$U$43)/'Valterra 26 Feb'!$A$41 -> 6625.0647 | R42: =(R41*'[7]Man Power'!$U$43)/'Valterra 26 Feb'!$A$41 -> 6625.0647 | S42: =(S41*'[7]Man Power'!$U$43)/'Valterra 26 Feb'!$A$41 -> 2208.3549 | U42: =(U41*'[7]Man Power'!$U$43)/'Valterra 26 Feb'!$A$41 -> 4416.7098 | V42: =(V41*'[7]Man Power'!$U$43)/'Valterra 26 Feb'!$A$41 -> 4416.7098 | W42: =(W41*'[7]Man Power'!$U$43)/'Valterra 26 Feb'!$A$41 -> 5520.8873 | X42: =(X41*'[7]Man Power'!$U$43)/'Valterra 26 Feb'!$A$41 -> 6625.0647 | Y42: =(Y41*'[7]Man Power'!$U$43)/'Valterra 26 Feb'!$A$41 -> 6625.0647 | Z42: =(Z41*'[7]Man Power'!$U$43)/'Valterra 26 Feb'!$A$41 -> 6625.0647 | AA42: =(AA41*'[7]Man Power'!$U$43)/'Valterra 26 Feb'!$A$41 -> 5520.8873 | AB42: =(AB41*'[7]Man Power'!$U$43)/'Valterra 26 Feb'!$A$41 -> 0 | AC42: =(AC41*'[7]Man Power'!$U$43)/'Valterra 26 Feb'!$A$41 -> 0 | AE42: =SUM(O42:S42,U42:AC42) -> 63925.026
B44: Schedule | E44: Status | F44: Oct | J44: Nov | X44: Nov | AB44: Nov
F45: W1 | H45: W3 | I45: W4 | J45: W1 | K45: W1 | M45: W3 | N45: W4 | V45: W3 | W45: W4 | X45: W1 | Y45: W2 | Z45: W3 | AA45: W4 | AB45: W1 | AC45: W2
B46: J-Leaf 295 Wp (1,500 pcs)
C47: Material Procurement | E47: TBC
...

Sheet Valterra 03 March
H1: j
B5: Summary Delivery Schedule
B6: Customer : Valterra
B8: No. | C8: Company | E8: Panel | F8: Quantity | H8: Oct-25 | M8: Nov-25 | R8: Material 800 Pcs 295W | V8: Oct-25 | Z8: Oct-25
H9: 40 | I9: 41 | J9: 42 | K9: 42 | M9: 44 | N9: 45 | O9: 46 | P9: 47 | V9: 40 | W9: 41 | X9: 42 | Y9: 43 | Z9: 40 | AA9: 41 | AB9: 42 | AC9: 43
B10: 1 | C10: IconGreen | E10: 295W Panel | F10: 1500 | J10: 800 | K10: 800 | R10: Materials | T10: Detail | U10: Amount | X10: 800 | Y10: 700 | AB10: 800 | AC10: 700 | AE10: Due Date
J11: 24 Oct | K11: 24 Oct | R11: 295W Module | T11: PIB+Penalty | U11: 110000000 | X11: 24 Oct | Y11: 31 Oct | AB11: 24 Oct | AC11: 31 Oct | AE11: This week | AH11: 150 | AI11: 45961
M12: 540 | R12: Potting Gel | T12: PIB | U12: 500000 | Y12: 150 | AC12: 150 | AE12: 45957 | AH12: 300 | AI12: 45966
M13: Beg Nov | R13: Masterbox | T13: DP | U13: 15000000 | Y13: 31 Oct | AC13: 31 Oct | AE13: This week | AH13: 240 | AI13: 45968
B15: Update, 10 March 2026
A17: Internal No | B17: No. | C17: Company | D17: PO | E17: Panel | F17: PO Qty | G17: Month | H17: 46023 | M17: Feb-26 | Q17: Mar-26 | V17: 46113 | Z17: 46143 | AE17: Total
G18: Week | H18: 1 | I18: 2 | J18: 3 | K18: 4 | L18: 5 | M18: 6 | N18: 7 | O18: 8 | P18: 9 | Q18: 10 | R18: 11 | S18: 12 | T18: 13 | U18: 14 | V18: 15 | W18: 16 | X18: 17 | Y18: 18 | Z18: 19 | AA18: 20 | AB18: 21 | AC18: 22
A19: 5 | B19: 1 | C19: Valterra | D19: PO609684 | E19: 50W | F19: 1000 | G19: Qty | N19: 540 | O19: 420 | R19: 40 | T19: Eid Al-Fitr Holiday | AG19: 5
G20: Date | N20: 14 Feb | O20: 21 Feb | R20: 46092 | AH20: 150 | AI20: 45961
A21: 6 | B21: 2 | D21: PO609804 | E21: 35W | F21: 1000 | G21: Qty | J21: 30 | K21: 90 | M21: 420 | N21: 450 | O21: 10 | AG21: 6
G22: Date | J22: 16 Jan | K22: 24 Jan | M22: 5 Feb | N22: 13 Feb | O22: 21 Feb
A23: 7 | B23: 3 | D23: PO609784 | E23: 50W | F23: 1000 | G23: Qty | R23: 140 | S23: 360 | U23: 500 | AG23: 7
G24: Date | R24: 46092 | S24: 46097 | U24: 46108
A25: 8 | B25: 4 | D25: PO609820 | E25: 35W | F25: 4000 | G25: Qty | O25: 320 | Q25: 180 | R25: 540 | S25: 900 | U25: 540 | V25: 720 | W25: 800 | AG25: 8
G26: Date | O26: 21 Feb | Q26: 46088 | R26: 46095 | S26: 46097 | U26: 46108 | V26: 46115 | W26: 46121
A27: 9 | B27: 5 | D27: PO609880 | E27: 50W | F27: 1000 | G27: Qty | W27: 1000 | AG27: 9
G28: Date | W28: 46123
A29: 4 | B29: 6 | D29: PO609614 | E29: 110W | F29: 1500 | G29: Qty | AB29: 1000 | AG29: 4
G30: Date | AB30: 46163
A31: 10 | B31: 7 | D31: PO609900 | E31: 50W | F31: 1000 | G31: Qty | X31: 1000 | AG31: 10
G32: Date | X32: 46129
A33: 11 | B33: 8 | D33: PO609915 | E33: 35W | F33: 2000 | G33: Qty | Y33: 2000 | AG33: 11
G34: Date | Y34: 46137
E35: 30W 3 Diode | F35: 5 | G35: Qty | S35: 5
G36: Date | S36: TBD
A37: 12 | B37: 9 | D37: PO609926 | E37: 50W | F37: 2000 | G37: Qty | Z37: 720 | AA37: 1280 | AG37: 12
G38: Date | Z38: 46144 | AA38: 46150
A39: 13 | B39: 10 | D39: PO609945 | E39: 50W | F39: 1000 | G39: Qty | AA39: 1000 | AG39: 13
G40: Date | AA40: 46154
A41: 16900 | C41: Salary Payment | G41: Working Day | M41: Paid | N41: Paid | O41: 3 | P41: 5 | Q41: 6 | R41: 6 | S41: 2 | U41: 4 | V41: 4 | W41: 5 | X41: 6 | Y41: 6 | Z41: 6 | AA41: 6 | AB41: 6 | AE41: =SUM(O41:S41,U41:AC41) -> 65
G42: Cost | O42: =54000000/A41 -> 3195.2663 | P42: =(P41*'[7]Man Power'!$U$43)/'Valterra 03 March'!$A$41 -> 5520.8873 | Q42: =(Q41*'[7]Man Power'!$U$43)/'Valterra 03 March'!$A$41 -> 6625.0647 | R42: =(R41*'[7]Man Power'!$U$43)/'Valterra 03 March'!$A$41 -> 6625.0647 | S42: =(S41*'[7]Man Power'!$U$43)/'Valterra 03 March'!$A$41 -> 2208.3549 | U42: =(U41*'[7]Man Power'!$U$43)/'Valterra 03 March'!$A$41 -> 4416.7098 | V42: =(V41*'[7]Man Power'!$U$43)/'Valterra 03 March'!$A$41 -> 4416.7098 | W42: =(W41*'[7]Man Power'!$U$43)/'Valterra 03 March'!$A$41 -> 5520.8873 | X42: =(X41*'[7]Man Power'!$U$43)/'Valterra 03 March'!$A$41 -> 6625.0647 | Y42: =(Y41*'[7]Man Power'!$U$43)/'Valterra 03 March'!$A$41 -> 6625.0647 | Z42: =(Z41*'[7]Man Power'!$U$43)/'Valterra 03 March'!$A$41 -> 6625.0647 | AA42: =(AA41*'[7]Man Power'!$U$43)/'Valterra 03 March'!$A$41 -> 6625.0647 | AB42: =(AB41*'[7]Man Power'!$U$43)/'Valterra 03 March'!$A$41 -> 6625.0647 | AC42: =(AC41*'[7]Man Power'!$U$43)/'Valterra 03 March'!$A$41 -> 0 | AE42: =SUM(O42:S42,U42:AC42) -> 71654.269
B44: Schedule | E44: Status | F44: Oct | J44: Nov | X44: Nov | AB44: Nov
F45: W1 | H45: W3 | I45: W4 | J45: W1 | K45: W1 | M45: W3 | N45: W4 | V45: W3 | W45: W4 | X45: W1 | Y45: W2 | Z45: W3 | AA45: W4 | AB45: W1 | AC45: W2
B46: J-Leaf 295 Wp (1,500 pcs)
C47: Material Procurement | E47: TBC
...

Sheet Schedule Production (1)
D2: February 2026
D3: MASTER PLANNING SCHEDULE
E5: Idle : | F5: =I5-N5 -> 7 | H5: Normal Days : | I5: 20 | M5: Working Days : | N5: =COUNT(P7:AP7) -> 13 | P5: S | Q5: M | R5: T | S5: W | T5: T | U5: F | V5: S | W5: S | X5: M | Y5: T | Z5: W | AA5: T | AB5: F | AC5: S | AD5: S | AE5: M | AF5: T | AG5: W | AH5: T | AI5: F | AJ5: S | AK5: S | AL5: M | AM5: T | AN5: W | AO5: T | AP5: F | AQ5: S
B6: No | C6: No PO | D6: Customers | E6: Detailed Product | H6: Qty (Order) | I6: Production Process | O6: Total Plan | P6: 1 | Q6: 2 | R6: 3 | S6: 4 | T6: 5 | U6: 6 | V6: 7 | W6: 8 | X6: 9 | Y6: 10 | Z6: 11 | AA6: 12 | AB6: 13 | AC6: 14 | AD6: 15 | AE6: 16 | AF6: 17 | AG6: 18 | AH6: 19 | AI6: 20 | AJ6: 21 | AK6: 22 | AL6: 23 | AM6: 24 | AN6: 25 | AO6: 26 | AP6: 27 | AQ6: 28
E7: Type | F7: Label | G7: Wp | X7: 2 | Y7: 2 | Z7: 2 | AA7: 2 | AB7: 2 | AC7: 2 | AE7: 2 | AF7: 2 | AG7: 2 | AH7: 2 | AI7: 1 | AO7: 2 | AP7: 2 | AQ7: 2
B8: 1 | C8: 00609804 (No.6) | D8: VALTERRA | E8: 73907-F | F8: THERMOKING | G8: 35 | H8: 1000 | I8: Prepration - Cutting Laser Module | O8: =SUM(P8:AP8) -> 450 | U8: 150 | X8: 160 | Y8: 140
I9: Instalation Junction Box - Packaging Process | O9: =SUM(P9:AQ9) -> 460 | X9: 240 | Y9: 220
B10: 2 | C10: 00609684 (No.5) | D10: VALTERRA | E10: 82882-C | F10: NAVIGATOR | G10: 50 | H10: 1000 | I10: Prepration - Cutting Laser Module | O10: =SUM(P10:AP10) -> 1000 | Y10: 80 | Z10: 240 | AA10: 240 | AB10: 240 | AC10: 200
I11: Instalation Junction Box - Packaging Process | O11: =SUM(P11:AQ11) -> 960 | Y11: 60 | Z11: 240 | AA11: 240 | AB11: 240 | AC11: 180
B12: 4 | C12: 00609820 (Part 1) (No.8) | D12: VALTERRA | E12: 73907-F | F12: THERMOKING | G12: 35 | H12: 500 | I12: Prepration - Cutting Laser Module | O12: =SUM(P12:AQ12) -> 500 | AG12: 180 | AH12: 240 | AI12: 80
I13: Instalation Junction Box - Packaging Process | O13: =SUM(P13:AQ13) -> 320 | AG13: 60 | AH13: 140 | AI13: 120
B14: 5. | C14: 00609820 (Part 2) (No.8) | D14: VALTERRA | E14: 73907-F | F14: THERMOKING | G14: 35 | H14: 1500 | I14: Prepration - Cutting Laser Module | O14: =SUM(P14:AQ14) -> 0
I15: Instalation Junction Box - Packaging Process | O15: =SUM(P15:AQ15) -> 0
B16: 5 | C16: 00609880 | D16: VALTERRA | E16: 82882-C | F16: THERMOKING | G16: 50 | H16: 1000 | I16: Prepration - Cutting Laser Module | O16: =SUM(P16:AP16) -> 0
I17: Instalation Junction Box - Packaging Process | O17: =SUM(P17:AQ17) -> 0
I22: Prepration - Cutting Laser Module | O22: =SUM(O8,O10,O12,O14) -> 1950 | AA22: 35W (PO.9804) | AE22: 50W (PO.9684) | AI22: 35W (PO.9804 & 9820) | AN22: 35W (PO.9820)
I23: Instalation Junction Box - Packaging Process | O23: =SUM(O9,O11,O13,O15) -> 1740 | AB23: 450 PCS (US) | AF23: 540 pcs (IRE) | AI23: 10 + 320 PCS (US) | AO23: 180 PCS | AQ23: (US)
AI24: 50W (PO.9684)
D25: March 2026 | AJ25: 420 pcs | AL25: (IRE)
D26: MASTER PLANNING SCHEDULE
E28: Idle : | F28: =I28-N28 -> 1 | H28: Normal Days : | I28: 19 | M28: Working Days : | N28: =COUNT(P30:AT30) -> 18 | P28: S | Q28: M | R28: T | S28: W | T28: T | U28: F | V28: S | W28: S | X28: M | Y28: T | Z28: W | AA28: T | AB28: F | AC28: S | AD28: S | AE28: M | AF28: T | AG28: W | AH28: T | AI28: F | AJ28: S | AK28: S | AL28: M | AM28: T | AN28: W | AO28: T | AP28: F | AQ28: S | AR28: S | AS28: M | AT28: T
B29: No | C29: No PO | D29: Customers | E29: Detailed Product | H29: Qty (Order) | I29: Production Process | O29: Total Plan | P29: 1 | Q29: 2 | R29: 3 | S29: 4 | T29: 5 | U29: 6 | V29: 7 | W29: 8 | X29: 9 | Y29: 10 | Z29: 11 | AA29: 12 | AB29: 13 | AC29: 14 | AD29: 15 | AE29: 16 | AF29: 17 | AG29: 18 | AH29: 19 | AI29: 20 | AJ29: 21 | AK29: 22 | AL29: 23 | AM29: 24 | AN29: 25 | AO29: 26 | AP29: 27 | AQ29: 28 | AR29: 29 | AS29: 30 | AT29: 31
E30: Type | F30: Label | G30: Wp | S30: 2 | T30: 2 | U30: 2 | V30: 2 | X30: 2 | Y30: 2 | Z30: 2 | AA30: 2 | AB30: 2 | AC30: 2 | AE30: 2 | AF30: 2 | AN30: 2 | AO30: 2 | AP30: 2 | AQ30: 2 | AS30: 2 | AT30: 2
B31: 1 | C31: 00609684 (No.5) | D31: VALTERRA | E31: 82882-C | F31: NAVIGATOR | G31: 50 | H31: 1000 | I31: Prepration - Cutting Laser Module | O31: =SUM(P31:AP31) -> 0
I32: Instalation Junction Box - Packaging Process | O32: =SUM(P32:AQ32) -> 40 | S32: 40
B33: 2 | C33: 00609820 (Part 1) (No.8) | D33: VALTERRA | E33: 73907-F | F33: THERMOKING | G33: 35 | H33: 500 | I33: Prepration - Cutting Laser Module | O33: =SUM(P33:AT33) -> 0
I34: Instalation Junction Box - Packaging Process | O34: =SUM(P34:AT34) -> 180 | S34: 180
B35: 3 | C35: 00609820 (Part 2) (No.8) | D35: VALTERRA | E35: 73907-F | F35: THERMOKING | G35: 35 | H35: 1500 | I35: Prepration - Cutting Laser Module | O35: =SUM(P35:AT35) -> 1500 | S35: 140 | T35: 180 | U35: 220 | X35: 200 | Y35: 240 | Z35: 240 | AA35: 160 | AB35: 120
I36: Instalation Junction Box - Packaging Process | O36: =SUM(P36:AT36) -> 1500 | S36: 140 | T36: 180 | U36: 220 | AB36: 140 | AC36: 180 | AD36: 220 | AE36: 240 | AF36: 180
B37: 4 | C37: 00609784 (No.7) | D37: VALTERRA | E37: 82882-C | F37: NAVIGATOR | G37: 50 | H37: 1000 | I37: Prepration - Cutting Laser Module | O37: =SUM(P37:AT37) -> 1000 | V37: 140 | AB37: 100 | AC37: 240 | AD37: 240 | AE37: 200 | AF37: 80
I38: Instalation Junction Box - Packaging Process | O38: =SUM(P38:AT38) -> 1000 | V38: 140 | AF38: 20 | AN38: 120 | AO38: 240 | AP38: 240 | AQ38: 240
B39: 5 | C39: 00609820 (Part 3) (No.8) | D39: VALTERRA | E39: 73907 - F | F39: THERMOKING | G39: 35 | H39: 2000 | I39: Prepration - Cutting Laser Module | O39: =SUM(P39:AT39) -> 1500 | AF39: 60 | AN39: 160 | AO39: 160 | AP39: 280 | AQ39: 280 | AS39: 280 | AT39: 280
I40: Instalation Junction Box - Packaging Process | O40: =SUM(P40:AT40) -> 460 | AS40: 180 | AT40: 280
I45: Prepration - Cutting Laser Module | O45: =SUM(O31,O33,O35,O37) -> 2500
I46: Instalation Junction Box - Packaging Process | O46: =SUM(O32,O34,O36,O38) -> 2720
D48: April 2026
D49: MASTER PLANNING SCHEDULE
E51: Idle : | F51: =I51-N51 -> -4 | H51: Normal Days : | I51: 19 | M51: Working Days : | N51: =COUNT(P53:AS53) -> 23 | P51: W | Q51: T | R51: F | S51: S | T51: S | U51: M | V51: T | W51: W | X51: T | Y51: F | Z51: S | AA51: S | AB51: M | AC51: T | AD51: W | AE51: T | AF51: F | AG51: S | AH51: S | AI51: M | AJ51: T | AK51: W | AL51: T | AM51: F | AN51: S | AO51: S | AP51: M | AQ51: T | AR51: W | AS51: T
B52: No | C52: No PO | D52: Customers | E52: Detailed Product | H52: Qty (Order) | I52: Production Process | O52: Total Plan | P52: 1 | Q52: 2 | R52: 3 | S52: 4 | T52: 5 | U52: 6 | V52: 7 | W52: 8 | X52: 9 | Y52: 10 | Z52: 11 | AA52: 12 | AB52: 13 | AC52: 14 | AD52: 15 | AE52: 16 | AF52: 17 | AG52: 18 | AH52: 19 | AI52: 20 | AJ52: 21 | AK52: 22 | AL52: 23 | AM52: 24 | AN52: 25 | AO52: 26 | AP52: 27 | AQ52: 28 | AR52: 29 | AS52: 30
E53: Type | F53: Label | G53: Wp | P53: 2 | Q53: 2 | V53: 2 | W53: 2 | X53: 2 | Y53: 2 | Z53: 2 | AB53: 2 | AC53: 2 | AD53: 2 | AE53: 2 | AF53: 2 | AG53: 2 | AI53: 2 | AJ53: 2 | AK53: 2 | AL53: 2 | AM53: 2 | AN53: 2 | AP53: 2 | AQ53: 2 | AR53: 2 | AS53: 2
...

Sheet Schedule Production (2)
D2: February 2026
D3: MASTER PLANNING SCHEDULE
E5: Idle : | F5: =I5-N5 -> 7 | H5: Normal Days : | I5: 20 | M5: Working Days : | N5: =COUNT(P7:AP7) -> 13 | P5: S | Q5: M | R5: T | S5: W | T5: T | U5: F | V5: S | W5: S | X5: M | Y5: T | Z5: W | AA5: T | AB5: F | AC5: S | AD5: S | AE5: M | AF5: T | AG5: W | AH5: T | AI5: F | AJ5: S | AK5: S | AL5: M | AM5: T | AN5: W | AO5: T | AP5: F | AQ5: S
B6: No | C6: No PO | D6: Customers | E6: Detailed Product | H6: Qty (Order) | I6: Production Process | O6: Total Plan | P6: 1 | Q6: 2 | R6: 3 | S6: 4 | T6: 5 | U6: 6 | V6: 7 | W6: 8 | X6: 9 | Y6: 10 | Z6: 11 | AA6: 12 | AB6: 13 | AC6: 14 | AD6: 15 | AE6: 16 | AF6: 17 | AG6: 18 | AH6: 19 | AI6: 20 | AJ6: 21 | AK6: 22 | AL6: 23 | AM6: 24 | AN6: 25 | AO6: 26 | AP6: 27 | AQ6: 28
E7: Type | F7: Label | G7: Wp | X7: 2 | Y7: 2 | Z7: 2 | AA7: 2 | AB7: 2 | AC7: 2 | AE7: 2 | AF7: 2 | AG7: 2 | AH7: 2 | AI7: 1 | AO7: 2 | AP7: 2 | AQ7: 2
B8: 1 | C8: 00609804 (No.6) | D8: VALTERRA | E8: 73907-F | F8: THERMOKING | G8: 35 | H8: 1000 | I8: Prepration - Cutting Laser Module | O8: =SUM(P8:AP8) -> 450 | U8: 150 | X8: 160 | Y8: 140
I9: Instalation Junction Box - Packaging Process | O9: =SUM(P9:AQ9) -> 460 | X9: 240 | Y9: 220
B10: 2 | C10: 00609684 (No.5) | D10: VALTERRA | E10: 82882-C | F10: NAVIGATOR | G10: 50 | H10: 1000 | I10: Prepration - Cutting Laser Module | O10: =SUM(P10:AP10) -> 1000 | Y10: 80 | Z10: 240 | AA10: 240 | AB10: 240 | AC10: 200
I11: Instalation Junction Box - Packaging Process | O11: =SUM(P11:AQ11) -> 960 | Y11: 60 | Z11: 240 | AA11: 240 | AB11: 240 | AC11: 180
B12: 4 | C12: 00609820 (Part 1) (No.8) | D12: VALTERRA | E12: 73907-F | F12: THERMOKING | G12: 35 | H12: 500 | I12: Prepration - Cutting Laser Module | O12: =SUM(P12:AQ12) -> 500 | AG12: 180 | AH12: 240 | AI12: 80
I13: Instalation Junction Box - Packaging Process | O13: =SUM(P13:AQ13) -> 320 | AG13: 60 | AH13: 140 | AI13: 120
B14: 5. | C14: 00609820 (Part 2) (No.8) | D14: VALTERRA | E14: 73907-F | F14: THERMOKING | G14: 35 | H14: 1500 | I14: Prepration - Cutting Laser Module | O14: =SUM(P14:AQ14) -> 0
I15: Instalation Junction Box - Packaging Process | O15: =SUM(P15:AQ15) -> 0
B16: 5 | C16: 00609880 | D16: VALTERRA | E16: 82882-C | F16: THERMOKING | G16: 50 | H16: 1000 | I16: Prepration - Cutting Laser Module | O16: =SUM(P16:AP16) -> 0
I17: Instalation Junction Box - Packaging Process | O17: =SUM(P17:AQ17) -> 0
I22: Prepration - Cutting Laser Module | O22: =SUM(O8,O10,O12,O14) -> 1950 | AA22: 35W (PO.9804) | AE22: 50W (PO.9684) | AI22: 35W (PO.9804 & 9820) | AN22: 35W (PO.9820)
I23: Instalation Junction Box - Packaging Process | O23: =SUM(O9,O11,O13,O15) -> 1740 | AB23: 450 PCS (US) | AF23: 540 pcs (IRE) | AI23: 10 + 320 PCS (US) | AO23: 180 PCS | AQ23: (US)
AI24: 50W (PO.9684)
D25: March 2026 | AJ25: 420 pcs | AL25: (IRE)
D26: MASTER PLANNING SCHEDULE
E28: Idle : | F28: =I28-N28 -> 0 | H28: Normal Days : | I28: 19 | M28: Working Days : | N28: =COUNT(P30:AT30) -> 19 | P28: S | Q28: M | R28: T | S28: W | T28: T | U28: F | V28: S | W28: S | X28: M | Y28: T | Z28: W | AA28: T | AB28: F | AC28: S | AD28: S | AE28: M | AF28: T | AG28: W | AH28: T | AI28: F | AJ28: S | AK28: S | AL28: M | AM28: T | AN28: W | AO28: T | AP28: F | AQ28: S | AR28: S | AS28: M | AT28: T
B29: No | C29: No PO | D29: Customers | E29: Detailed Product | H29: Qty (Order) | I29: Production Process | O29: Total Plan | P29: 1 | Q29: 2 | R29: 3 | S29: 4 | T29: 5 | U29: 6 | V29: 7 | W29: 8 | X29: 9 | Y29: 10 | Z29: 11 | AA29: 12 | AB29: 13 | AC29: 14 | AD29: 15 | AE29: 16 | AF29: 17 | AG29: 18 | AH29: 19 | AI29: 20 | AJ29: 21 | AK29: 22 | AL29: 23 | AM29: 24 | AN29: 25 | AO29: 26 | AP29: 27 | AQ29: 28 | AR29: 29 | AS29: 30 | AT29: 31
E30: Type | F30: Label | G30: Wp | T30: 1 | U30: 2 | V30: 2 | W30: 2 | X30: 2 | Y30: 2 | Z30: 2 | AA30: 2 | AB30: 2 | AC30: 2 | AD30: 2 | AE30: 2 | AF30: 2 | AN30: 2 | AO30: 2 | AP30: 2 | AQ30: 2 | AS30: 2 | AT30: 2
B31: 1 | C31: 00609684 (No.5) | D31: VALTERRA | E31: 82882-C | F31: NAVIGATOR | G31: 50 | H31: 1000 | I31: Prepration - Cutting Laser Module | O31: =SUM(P31:AP31) -> 0
I32: Instalation Junction Box - Packaging Process | O32: =SUM(P32:AQ32) -> 40 | T32: 40
B33: 2 | C33: 00609820 (Part 1) (No.8) | D33: VALTERRA | E33: 73907-F | F33: THERMOKING | G33: 35 | H33: 500 | I33: Prepration - Cutting Laser Module | O33: =SUM(P33:AT33) -> 0
I34: Instalation Junction Box - Packaging Process | O34: =SUM(P34:AT34) -> 180 | T34: 180
B35: 3 | C35: 00609820 (Part 2) (No.8) | D35: VALTERRA | E35: 73907-F | F35: THERMOKING | G35: 35 | H35: 1500 | I35: Prepration - Cutting Laser Module | O35: =SUM(P35:AT35) -> 1500 | U35: 160 | V35: 220 | W35: 280 | X35: 280 | Y35: 80 | Z35: 280 | AA35: 200
I36: Instalation Junction Box - Packaging Process | O36: =SUM(P36:AT36) -> 1500 | U36: 80 | V36: 140 | W36: 240 | X36: 80 | AC36: 600 | AD36: 300 | AE36: 60
B37: 4 | C37: 00609784 (No.7) | D37: VALTERRA | E37: 82882-C | F37: NAVIGATOR | G37: 50 | H37: 1000 | I37: Prepration - Cutting Laser Module | O37: =SUM(P37:AT37) -> 1000 | Y37: 140 | AB37: 240 | AC37: 160 | AE37: 240 | AF37: 120 | AN37: 100
I38: Instalation Junction Box - Packaging Process | O38: =SUM(P38:AT38) -> 1000 | Y38: 140 | AD38: 400 | AE38: 140 | AF38: 160 | AN38: 160
B39: 5 | C39: 00609820 (Part 3) (No.8) | D39: VALTERRA | E39: 73907 - F | F39: THERMOKING | G39: 35 | H39: 2000 | I39: Prepration - Cutting Laser Module | O39: =SUM(P39:AT39) -> 1360 | AO39: 240 | AP39: 280 | AQ39: 280 | AS39: 280 | AT39: 280
I40: Instalation Junction Box - Packaging Process | O40: =SUM(P40:AT40) -> 1360 | AO40: 240 | AP40: 280 | AQ40: 280 | AS40: 280 | AT40: 280
I45: Prepration - Cutting Laser Module | O45: =SUM(O31,O33,O35,O37) -> 2500 | V45: 35W (PO.9820) | Y45: 35W (PO.9820) | AB45: 50W (PO.9684 & 9784) | AF45: 35W PO.9820 | AP45: 35W (PO.9820) | AS45: 35W (PO.9820)
I46: Instalation Junction Box - Packaging Process | O46: =SUM(O32,O34,O36,O38) -> 2720 | V46: 180 pcs | Y46: 540 PCS | AB46: 40 + 140 PCS | AF46: 900 pcs | AP46: 540 | AS46: =1460-540 -> 920
AF47: 50W PO.9784
D48: April 2026 | AF48: 540 pcs
D49: MASTER PLANNING SCHEDULE
E51: Idle : | F51: =I51-N51 -> -4 | H51: Normal Days : | I51: 19 | M51: Working Days : | N51: =COUNT(P53:AS53) -> 23 | P51: W | Q51: T | R51: F | S51: S | T51: S | U51: M | V51: T | W51: W | X51: T | Y51: F | Z51: S | AA51: S | AB51: M | AC51: T | AD51: W | AE51: T | AF51: F | AG51: S | AH51: S | AI51: M | AJ51: T | AK51: W | AL51: T | AM51: F | AN51: S | AO51: S | AP51: M | AQ51: T | AR51: W | AS51: T
B52: No | C52: No PO | D52: Customers | E52: Detailed Product | H52: Qty (Order) | I52: Production Process | O52: Total Plan | P52: 1 | Q52: 2 | R52: 3 | S52: 4 | T52: 5 | U52: 6 | V52: 7 | W52: 8 | X52: 9 | Y52: 10 | Z52: 11 | AA52: 12 | AB52: 13 | AC52: 14 | AD52: 15 | AE52: 16 | AF52: 17 | AG52: 18 | AH52: 19 | AI52: 20 | AJ52: 21 | AK52: 22 | AL52: 23 | AM52: 24 | AN52: 25 | AO52: 26 | AP52: 27 | AQ52: 28 | AR52: 29 | AS52: 30
...

Sheet Schedule Production (Original)
D2: February 2026
D3: MASTER PLANNING SCHEDULE
E5: Idle : | F5: =I5-N5 -> 7 | H5: Normal Days : | I5: 20 | M5: Working Days : | N5: =COUNT(P7:AP7) -> 13 | P5: S | Q5: M | R5: T | S5: W | T5: T | U5: F | V5: S | W5: S | X5: M | Y5: T | Z5: W | AA5: T | AB5: F | AC5: S | AD5: S | AE5: M | AF5: T | AG5: W | AH5: T | AI5: F | AJ5: S | AK5: S | AL5: M | AM5: T | AN5: W | AO5: T | AP5: F | AQ5: S
B6: No | C6: No PO | D6: Customers | E6: Detailed Product | H6: Qty (Order) | I6: Production Process | O6: Total Plan | P6: 1 | Q6: 2 | R6: 3 | S6: 4 | T6: 5 | U6: 6 | V6: 7 | W6: 8 | X6: 9 | Y6: 10 | Z6: 11 | AA6: 12 | AB6: 13 | AC6: 14 | AD6: 15 | AE6: 16 | AF6: 17 | AG6: 18 | AH6: 19 | AI6: 20 | AJ6: 21 | AK6: 22 | AL6: 23 | AM6: 24 | AN6: 25 | AO6: 26 | AP6: 27 | AQ6: 28
E7: Type | F7: Label | G7: Wp | X7: 2 | Y7: 2 | Z7: 2 | AA7: 2 | AB7: 2 | AC7: 2 | AE7: 2 | AF7: 2 | AG7: 2 | AH7: 2 | AI7: 1 | AO7: 2 | AP7: 2 | AQ7: 2
B8: 1 | C8: 00609804 (No.6) | D8: VALTERRA | E8: 73907-F | F8: THERMOKING | G8: 35 | H8: 1000 | I8: Prepration - Cutting Laser Module | O8: =SUM(P8:AP8) -> 450 | U8: 150 | X8: 160 | Y8: 140
I9: Instalation Junction Box - Packaging Process | O9: =SUM(P9:AQ9) -> 460 | X9: 240 | Y9: 220
B10: 2 | C10: 00609684 (No.5) | D10: VALTERRA | E10: 82882-C | F10: NAVIGATOR | G10: 50 | H10: 1000 | I10: Prepration - Cutting Laser Module | O10: =SUM(P10:AP10) -> 1000 | Y10: 80 | Z10: 240 | AA10: 240 | AB10: 240 | AC10: 200
I11: Instalation Junction Box - Packaging Process | O11: =SUM(P11:AQ11) -> 960 | Y11: 60 | Z11: 240 | AA11: 240 | AB11: 240 | AC11: 180
B12: 4 | C12: 00609820 (Part 1) (No.8) | D12: VALTERRA | E12: 73907-F | F12: THERMOKING | G12: 35 | H12: 500 | I12: Prepration - Cutting Laser Module | O12: =SUM(P12:AQ12) -> 500 | AG12: 180 | AH12: 240 | AI12: 80
I13: Instalation Junction Box - Packaging Process | O13: =SUM(P13:AQ13) -> 320 | AG13: 60 | AH13: 140 | AI13: 120
B14: 5. | C14: 00609820 (Part 2) (No.8) | D14: VALTERRA | E14: 73907-F | F14: THERMOKING | G14: 35 | H14: 1500 | I14: Prepration - Cutting Laser Module | O14: =SUM(P14:AQ14) -> 0
I15: Instalation Junction Box - Packaging Process | O15: =SUM(P15:AQ15) -> 0
B16: 5 | C16: 00609880 | D16: VALTERRA | E16: 82882-C | F16: THERMOKING | G16: 50 | H16: 1000 | I16: Prepration - Cutting Laser Module | O16: =SUM(P16:AP16) -> 0
I17: Instalation Junction Box - Packaging Process | O17: =SUM(P17:AQ17) -> 0
I22: Prepration - Cutting Laser Module | O22: =SUM(O8,O10,O12,O14) -> 1950 | AA22: 35W (PO.9804) | AE22: 50W (PO.9684) | AI22: 35W (PO.9804 & 9820) | AN22: 35W (PO.9820)
I23: Instalation Junction Box - Packaging Process | O23: =SUM(O9,O11,O13,O15) -> 1740 | AB23: 450 PCS (US) | AF23: 540 pcs (IRE) | AI23: 10 + 320 PCS (US) | AO23: 180 PCS | AQ23: (US)
AI24: 50W (PO.9684)
D25: March 2026 | AJ25: 420 pcs | AL25: (IRE)
D26: MASTER PLANNING SCHEDULE
E28: Idle : | F28: =I28-N28 -> 1 | H28: Normal Days : | I28: 19 | M28: Working Days : | N28: =COUNT(P30:AT30) -> 18 | P28: S | Q28: M | R28: T | S28: W | T28: T | U28: F | V28: S | W28: S | X28: M | Y28: T | Z28: W | AA28: T | AB28: F | AC28: S | AD28: S | AE28: M | AF28: T | AG28: W | AH28: T | AI28: F | AJ28: S | AK28: S | AL28: M | AM28: T | AN28: W | AO28: T | AP28: F | AQ28: S | AR28: S | AS28: M | AT28: T
B29: No | C29: No PO | D29: Customers | E29: Detailed Product | H29: Qty (Order) | I29: Production Process | O29: Total Plan | P29: 1 | Q29: 2 | R29: 3 | S29: 4 | T29: 5 | U29: 6 | V29: 7 | W29: 8 | X29: 9 | Y29: 10 | Z29: 11 | AA29: 12 | AB29: 13 | AC29: 14 | AD29: 15 | AE29: 16 | AF29: 17 | AG29: 18 | AH29: 19 | AI29: 20 | AJ29: 21 | AK29: 22 | AL29: 23 | AM29: 24 | AN29: 25 | AO29: 26 | AP29: 27 | AQ29: 28 | AR29: 29 | AS29: 30 | AT29: 31
E30: Type | F30: Label | G30: Wp | T30: 1 | U30: 2 | V30: 2 | W30: 2 | X30: 2 | Y30: 2 | Z30: 2 | AA30: 2 | AB30: 2 | AC30: 2 | AD30: 2 | AE30: 1 | AN30: 2 | AO30: 2 | AP30: 2 | AQ30: 2 | AS30: 2 | AT30: 2
B31: 1 | C31: 00609684 (No.5) | D31: VALTERRA | E31: 82882-C | F31: NAVIGATOR | G31: 50 | H31: 1000 | I31: Prepration - Cutting Laser Module | O31: =SUM(P31:AP31) -> 0
I32: Instalation Junction Box - Packaging Process | O32: =SUM(P32:AQ32) -> 40 | T32: 40
B33: 2 | C33: 00609820 (Part 1) (No.8) | D33: VALTERRA | E33: 73907-F | F33: THERMOKING | G33: 35 | H33: 500 | I33: Prepration - Cutting Laser Module | O33: =SUM(P33:AT33) -> 0
I34: Instalation Junction Box - Packaging Process | O34: =SUM(P34:AT34) -> 180 | T34: 180
B35: 3 | C35: 00609820 (Part 2) (No.8) | D35: VALTERRA | E35: 73907-F | F35: THERMOKING | G35: 35 | H35: 1500 | I35: Prepration - Cutting Laser Module | O35: =SUM(P35:AT35) -> 1500 | V35: 240 | W35: 300 | X35: 140 | Y35: 300 | Z35: 300 | AA35: 220
I36: Instalation Junction Box - Packaging Process | O36: =SUM(P36:AT36) -> 1500 | V36: 240 | W36: 300 | AC36: 400 | AD36: 500 | AN36: 60
B37: 4 | C37: 00609784 (No.7) | D37: VALTERRA | E37: 82882-C | F37: NAVIGATOR | G37: 50 | H37: 1000 | I37: Prepration - Cutting Laser Module | O37: =SUM(P37:AT37) -> 1000 | X37: 140 | AB37: 240 | AC37: 120 | AN37: 200 | AO37: 240 | AP37: 60
I38: Instalation Junction Box - Packaging Process | O38: =SUM(P38:AT38) -> 1000 | X38: 140 | AD38: 360 | AN38: 80 | AO38: 280 | AP38: 140
B39: 5 | C39: 00609820 (Part 3) (No.8) | D39: VALTERRA | E39: 73907 - F | F39: THERMOKING | G39: 35 | H39: 2000 | I39: Prepration - Cutting Laser Module | O39: =SUM(P39:AT39) -> 1240 | AE39: 120 | AP39: 280 | AQ39: 280 | AS39: 280 | AT39: 280
I40: Instalation Junction Box - Packaging Process | O40: =SUM(P40:AT40) -> 1060 | AE40: 80 | AP40: 140 | AQ40: 280 | AS40: 280 | AT40: 280
I45: Prepration - Cutting Laser Module | O45: =SUM(O31,O33,O35,O37) -> 2500 | V45: 35W (PO.9820) | Y45: 35W (PO.9820) | AB45: 50W (PO.9684 & 9784) | AF45: 35W PO.9820 | AP45: 35W (PO.9820) | AS45: 50W (PO.9784)
I46: Instalation Junction Box - Packaging Process | O46: =SUM(O32,O34,O36,O38) -> 2720 | V46: 180 pcs | Y46: 540 PCS | AB46: 40 + 140 PCS | AF46: 900 pcs | AP46: 540 | AS46: 500
AF47: 50W PO.9784
D48: April 2026 | O48: =O39+O54 -> 2000 | AF48: 360 pcs
D49: MASTER PLANNING SCHEDULE | O49: =O40+O55 -> 2000
E51: Idle : | F51: =I51-N51 -> -4 | H51: Normal Days : | I51: 19 | M51: Working Days : | N51: =COUNT(P53:AS53) -> 23 | P51: W | Q51: T | R51: F | S51: S | T51: S | U51: M | V51: T | W51: W | X51: T | Y51: F | Z51: S | AA51: S | AB51: M | AC51: T | AD51: W | AE51: T | AF51: F | AG51: S | AH51: S | AI51: M | AJ51: T | AK51: W | AL51: T | AM51: F | AN51: S | AO51: S | AP51: M | AQ51: T | AR51: W | AS51: T
B52: No | C52: No PO | D52: Customers | E52: Detailed Product | H52: Qty (Order) | I52: Production Process | O52: Total Plan | P52: 1 | Q52: 2 | R52: 3 | S52: 4 | T52: 5 | U52: 6 | V52: 7 | W52: 8 | X52: 9 | Y52: 10 | Z52: 11 | AA52: 12 | AB52: 13 | AC52: 14 | AD52: 15 | AE52: 16 | AF52: 17 | AG52: 18 | AH52: 19 | AI52: 20 | AJ52: 21 | AK52: 22 | AL52: 23 | AM52: 24 | AN52: 25 | AO52: 26 | AP52: 27 | AQ52: 28 | AR52: 29 | AS52: 30
...

Sheet Schedule (If EVA Delay)
D2: February 2026
D3: MASTER PLANNING SCHEDULE
E5: Idle : | F5: =I5-N5 -> 7 | H5: Normal Days : | I5: 20 | M5: Working Days : | N5: =COUNT(P7:AP7) -> 13 | P5: S | Q5: M | R5: T | S5: W | T5: T | U5: F | V5: S | W5: S | X5: M | Y5: T | Z5: W | AA5: T | AB5: F | AC5: S | AD5: S | AE5: M | AF5: T | AG5: W | AH5: T | AI5: F | AJ5: S | AK5: S | AL5: M | AM5: T | AN5: W | AO5: T | AP5: F | AQ5: S
B6: No | C6: No PO | D6: Customers | E6: Detailed Product | H6: Qty (Order) | I6: Production Process | O6: Total Plan | P6: 1 | Q6: 2 | R6: 3 | S6: 4 | T6: 5 | U6: 6 | V6: 7 | W6: 8 | X6: 9 | Y6: 10 | Z6: 11 | AA6: 12 | AB6: 13 | AC6: 14 | AD6: 15 | AE6: 16 | AF6: 17 | AG6: 18 | AH6: 19 | AI6: 20 | AJ6: 21 | AK6: 22 | AL6: 23 | AM6: 24 | AN6: 25 | AO6: 26 | AP6: 27 | AQ6: 28
E7: Type | F7: Label | G7: Wp | X7: 2 | Y7: 2 | Z7: 2 | AA7: 2 | AB7: 2 | AC7: 2 | AE7: 2 | AF7: 2 | AG7: 2 | AH7: 2 | AI7: 1 | AO7: 2 | AP7: 2 | AQ7: 2
B8: 1 | C8: 00609804 (No.6) | D8: VALTERRA | E8: 73907-F | F8: THERMOKING | G8: 35 | H8: 1000 | I8: Prepration - Cutting Laser Module | O8: =SUM(P8:AP8) -> 450 | U8: 150 | X8: 160 | Y8: 140
I9: Instalation Junction Box - Packaging Process | O9: =SUM(P9:AQ9) -> 460 | X9: 240 | Y9: 220
B10: 2 | C10: 00609684 (No.5) | D10: VALTERRA | E10: 82882-C | F10: NAVIGATOR | G10: 50 | H10: 1000 | I10: Prepration - Cutting Laser Module | O10: =SUM(P10:AP10) -> 1000 | Y10: 80 | Z10: 240 | AA10: 240 | AB10: 240 | AC10: 200
I11: Instalation Junction Box - Packaging Process | O11: =SUM(P11:AQ11) -> 960 | Y11: 60 | Z11: 240 | AA11: 240 | AB11: 240 | AC11: 180
B12: 4 | C12: 00609820 (Part 1) (No.8) | D12: VALTERRA | E12: 73907-F | F12: THERMOKING | G12: 35 | H12: 500 | I12: Prepration - Cutting Laser Module | O12: =SUM(P12:AQ12) -> 500 | AG12: 180 | AH12: 240 | AI12: 80
I13: Instalation Junction Box - Packaging Process | O13: =SUM(P13:AQ13) -> 320 | AG13: 60 | AH13: 140 | AI13: 120
B14: 5. | C14: 00609820 (Part 2) (No.8) | D14: VALTERRA | E14: 73907-F | F14: THERMOKING | G14: 35 | H14: 1500 | I14: Prepration - Cutting Laser Module | O14: =SUM(P14:AQ14) -> 0
I15: Instalation Junction Box - Packaging Process | O15: =SUM(P15:AQ15) -> 0
B16: 5 | C16: 00609880 | D16: VALTERRA | E16: 82882-C | F16: THERMOKING | G16: 50 | H16: 1000 | I16: Prepration - Cutting Laser Module | O16: =SUM(P16:AP16) -> 0
I17: Instalation Junction Box - Packaging Process | O17: =SUM(P17:AQ17) -> 0
I22: Prepration - Cutting Laser Module | O22: =SUM(O8,O10,O12,O14) -> 1950 | AA22: 35W (PO.9804) | AE22: 50W (PO.9684) | AI22: 35W (PO.9804 & 9820) | AN22: 35W (PO.9820)
I23: Instalation Junction Box - Packaging Process | O23: =SUM(O9,O11,O13,O15) -> 1740 | AB23: 450 PCS (US) | AF23: 540 pcs (IRE) | AI23: 10 + 320 PCS (US) | AO23: 180 PCS | AQ23: (US)
AI24: 50W (PO.9684)
D25: March 2026 | AJ25: 420 pcs | AL25: (IRE) | AR25: =540/90 -> 6
D26: MASTER PLANNING SCHEDULE
E28: Idle : | F28: =I28-N28 -> 1 | H28: Normal Days : | I28: 19 | M28: Working Days : | N28: =COUNT(P30:AT30) -> 18 | P28: S | Q28: M | R28: T | S28: W | T28: T | U28: F | V28: S | W28: S | X28: M | Y28: T | Z28: W | AA28: T | AB28: F | AC28: S | AD28: S | AE28: M | AF28: T | AG28: W | AH28: T | AI28: F | AJ28: S | AK28: S | AL28: M | AM28: T | AN28: W | AO28: T | AP28: F | AQ28: S | AR28: S | AS28: M | AT28: T
B29: No | C29: No PO | D29: Customers | E29: Detailed Product | H29: Qty (Order) | I29: Production Process | O29: Total Plan | P29: 1 | Q29: 2 | R29: 3 | S29: 4 | T29: 5 | U29: 6 | V29: 7 | W29: 8 | X29: 9 | Y29: 10 | Z29: 11 | AA29: 12 | AB29: 13 | AC29: 14 | AD29: 15 | AE29: 16 | AF29: 17 | AG29: 18 | AH29: 19 | AI29: 20 | AJ29: 21 | AK29: 22 | AL29: 23 | AM29: 24 | AN29: 25 | AO29: 26 | AP29: 27 | AQ29: 28 | AR29: 29 | AS29: 30 | AT29: 31
E30: Type | F30: Label | G30: Wp | T30: 1 | U30: 2 | V30: 2 | W30: 2 | X30: 2 | Y30: 2 | Z30: 2 | AA30: 2 | AB30: 2 | AC30: 2 | AD30: 2 | AE30: 1 | AN30: 2 | AO30: 2 | AP30: 2 | AQ30: 2 | AS30: 2 | AT30: 2
B31: 1 | C31: 00609684 (No.5) | D31: VALTERRA | E31: 82882-C | F31: NAVIGATOR | G31: 50 | H31: 1000 | I31: Prepration - Cutting Laser Module | O31: =SUM(P31:AP31) -> 0 | AV31: Note : Delivery for 50W PO.9784 1. Pickup, Sunday 29th March & Freight 30 March 2. Pickup Monday 30th March & Freight 31 March
I32: Instalation Junction Box - Packaging Process | O32: =SUM(P32:AQ32) -> 40 | T32: 40
B33: 2 | C33: 00609820 (Part 1) (No.8) | D33: VALTERRA | E33: 73907-F | F33: THERMOKING | G33: 35 | H33: 500 | I33: Prepration - Cutting Laser Module | O33: =SUM(P33:AT33) -> 0
I34: Instalation Junction Box - Packaging Process | O34: =SUM(P34:AT34) -> 180 | T34: 180
B35: 3 | C35: 00609820 (Part 2) (No.8) | D35: VALTERRA | E35: 73907-F | F35: THERMOKING | G35: 35 | H35: 1500 | I35: Prepration - Cutting Laser Module | O35: =SUM(P35:AT35) -> 1500 | V35: 240 | W35: 300 | X35: 140 | Y35: 300 | Z35: 300 | AA35: 220
I36: Instalation Junction Box - Packaging Process | O36: =SUM(P36:AT36) -> 1500 | V36: 240 | W36: 300 | AC36: 400 | AD36: 500 | AN36: 60
B37: 4 | C37: 00609784 (No.7) | D37: VALTERRA | E37: 82882-C | F37: NAVIGATOR | G37: 50 | H37: 1000 | I37: Prepration - Cutting Laser Module | O37: =SUM(P37:AT37) -> 1000 | X37: 140 | AB37: 240 | AC37: 120 | AE37: 20 | AP37: 240 | AQ37: 240
I38: Instalation Junction Box - Packaging Process | O38: =SUM(P38:AT38) -> 1000 | X38: 140 | AD38: 360 | AP38: 220 | AQ38: 280
B39: 5 | C39: 00609820 (Part 3) (No.8) | D39: VALTERRA | E39: 73907 - F | F39: THERMOKING | G39: 35 | H39: 2000 | I39: Prepration - Cutting Laser Module | O39: =SUM(P39:AT39) -> 1060 | AN39: 220 | AO39: 280 | AS39: 280 | AT39: 280
I40: Instalation Junction Box - Packaging Process | O40: =SUM(P40:AT40) -> 1040 | AN40: 180 | AO40: 280 | AP40: 20 | AS40: 280 | AT40: 280
I45: Prepration - Cutting Laser Module | O45: =SUM(O31,O33,O35,O37) -> 2500 | V45: 35W (PO.9820) | Y45: 35W (PO.9820) | AB45: 50W (PO.9684 & 9784) | AF45: 35W PO.9820 | AP45: 35W (PO.9820) | AS45: 50W (PO.9784)
I46: Instalation Junction Box - Packaging Process | O46: =SUM(O32,O34,O36,O38) -> 2720 | V46: 180 pcs | Y46: 540 PCS | AB46: 40 + 140 PCS | AF46: 900 pcs | AP46: 540 | AS46: 500
AF47: 50W PO.9784
D48: April 2026 | O48: =O39+O54 -> 2000 | AF48: 360 pcs
D49: MASTER PLANNING SCHEDULE | O49: =O40+O55 -> 2000
E51: Idle : | F51: =I51-N51 -> -4 | H51: Normal Days : | I51: 19 | M51: Working Days : | N51: =COUNT(P53:AS53) -> 23 | P51: W | Q51: T | R51: F | S51: S | T51: S | U51: M | V51: T | W51: W | X51: T | Y51: F | Z51: S | AA51: S | AB51: M | AC51: T | AD51: W | AE51: T | AF51: F | AG51: S | AH51: S | AI51: M | AJ51: T | AK51: W | AL51: T | AM51: F | AN51: S | AO51: S | AP51: M | AQ51: T | AR51: W | AS51: T
B52: No | C52: No PO | D52: Customers | E52: Detailed Product | H52: Qty (Order) | I52: Production Process | O52: Total Plan | P52: 1 | Q52: 2 | R52: 3 | S52: 4 | T52: 5 | U52: 6 | V52: 7 | W52: 8 | X52: 9 | Y52: 10 | Z52: 11 | AA52: 12 | AB52: 13 | AC52: 14 | AD52: 15 | AE52: 16 | AF52: 17 | AG52: 18 | AH52: 19 | AI52: 20 | AJ52: 21 | AK52: 22 | AL52: 23 | AM52: 24 | AN52: 25 | AO52: 26 | AP52: 27 | AQ52: 28 | AR52: 29 | AS52: 30
...

Sheet Man Power
G2: MONITORING PLANNING | AA2: Calculation Cost
G3: LABOR COST | I3: FEBRUARY 2026 | U3: Apendix 3 | AA3: Direct Labor | AC3: Valterra Project
D5: Shift 1 | G5: Direct Labor | L5: Qty | M5: Total | O5: Shift 2 | P5: Direct Labor | U5: Qty | V5: Total | Y5: No | Z5: Month | AA5: Working Day | AE5: Man Power | AF5: Cost
G6: Station | I6: Process | P6: Station | S6: Process | AA6: Days | AC6: Shift | AD6: Qty | AF6: / Day | AG6: Month
G8: ▪ | H8: Preparation | I8: Sortr Cell & Cutting Cell | L8: 2 | M8: =SUM(L8:L19) -> 25 | P8: ▪ | Q8: Preparation | S8: Sortr Cell & Cutting Cell | U8: 2 | V8: =SUM(U8:U19) -> 25 | Y8: 1 | Z8: March | AA8: a. | AB8: Normal Days | AC8: 2 | AD8: 15 | AE8: 80 | AF8: =$U$43 -> 18660599 | AG8: =AD8*AF8 -> 279908985
I9: Cutting Eva & Backsheet | L9: 2 | S9: Cutting Eva & Backsheet | U9: 2 | AA9: b. | AB9: Saturday | AC9: 2 | AD9: 3 | AE9: 80 | AF9: =SUM($U$43,$U$47) -> 19271203 | AG9: =AF9*AD9 -> 57813610
I10: Cutting Ribbon & Busbar | L10: 1 | S10: Cutting Ribbon & Busbar | U10: 1 | AC10: Total : | AD10: =SUM(AD8:AD9) -> 18 | AG10: =SUM(AG8:AG9) -> 3.377226e+08
I11: Assembling Junction Box | L11: 2 | S11: Assembling Junction Box | U11: 2 | Y11: 2. | Z11: April | AA11: a. | AB11: Normal Days | AC11: 2 | AD11: 20 | AE11: 80 | AF11: =$U$43 -> 18660599 | AG11: =AD11*AF11 -> 373211980
G12: ▪ | H12: Soldering | I12: Series Soldering | L12: 5 | P12: ▪ | Q12: Soldering | S12: Series Soldering | U12: 5 | AA12: b. | AB12: Saturday | AC12: 2 | AD12: 3 | AE12: 80 | AF12: =SUM($U$43,$U$47) -> 19271203 | AG12: =AF12*AD12 -> 57813610
I13: Lay - Up (Assymbling Module) | L13: 6 | S13: Lay - Up (Assymbling Module) | U13: 6 | AC13: Total : | AD13: =SUM(AD11:AD12) -> 23 | AG13: =SUM(AG11:AG12) -> 4.3102559e+08
G14: ▪ | H14: Inspection Quality | I14: EL - Test | L14: 1 | P14: ▪ | Q14: Inspection Quality | S14: EL - Test | U14: 1 | Y14: 3. | Z14: May | AA14: a. | AB14: Normal Days | AC14: 2 | AD14: 15 | AE14: 80 | AF14: =$U$43 -> 18660599 | AG14: =AD14*AF14 -> 279908985
I15: Visual Check | L15: 2 | S15: Visual Check | U15: 2 | AA15: b. | AB15: Saturday | AC15: 2 | AD15: 3 | AE15: 80 | AF15: =SUM($U$43,$U$47) -> 19271203 | AG15: =AF15*AD15 -> 57813610
G16: ▪ | H16: Laminating | I16: Laminated Process | L16: 2 | P16: ▪ | Q16: Laminating | S16: Laminated Process | U16: 2 | AC16: Total : | AD16: =SUM(AD14:AD15) -> 18 | AG16: =SUM(AG14:AG15) -> 3.377226e+08
I17: Application Protection Film | S17: Application Protection Film | AC17: Grand Total : | AD17: =SUM(AD10,AD13,AD16) -> 59 | AG17: =SUM(AG10,AG13,AG16) -> 1.1064708e+09
G18: ▪ | H18: Assymbling | I18: Cutting Module & Instalasi Grommet | L18: 2 | P18: ▪ | Q18: Assymbling | S18: Cutting Module & Instalasi Grommet | U18: 2
H19: Additional Man Power | Q19: Additional Man Power
D21: Non Shift | G21: Direct Labor | L21: Qty | M21: Total | O21: Shift 1 & 2 | P21: Direct Labor | U21: Qty | V21: Total | Y21: No | Z21: Working Day | AE21: Man Power | AF21: Cost
G22: Station | I22: Process | P22: Station | S22: Process | Z22: Days | AC22: Shift | AD22: Qty | AF22: / Day | AG22: Month
G24: ▪ | H24: Assymbling | I24: Instalasi Junction Box | L24: 2 | M24: =SUM(L24:L30) -> 16 | P24: ▪ | Q24: Production | S24: Leader Production (Permanent) | U24: 4 | V24: =SUM(U24:U35) -> 14 | Y24: 1 | Z24: Monday - Friday | AC24: 2 | AD24: 1 | AE24: 80 | AF24: =$U$43/16000 -> 1166.2874 | AG24: =AD24*AF24 -> 1166.2874
G25: ▪ | H25: Inspection Quality | I25: Test IV (Sunsimulator) | L25: 1 | S25: Raw Material (Daily) | U25: 1 | Y25: 2 | Z25: Saturday | AC25: 2 | AD25: 1 | AE25: 80 | AF25: =SUM($U$43,$U$47)/16000 -> 1204.4502 | AG25: =AF25*AD25 -> 1204.4502
I26: EL - Test | L26: 1 | S26: Officer Production (Daily) | U26: 1 | AC26: Grand Total : | AD26: =SUM(AD24:AD25) -> 2 | AG26: =SUM(AG24:AG25) -> 2370.7377
G27: ▪ | H27: Coating Process | I27: Application Potting gell | L27: 2 | P27: ▪ | Q27: Quality Control | S27: Quality Process Shift 1 (Daily) | U27: 1 | AG27: =AG26/16000 -> 0.1481711
G28: ▪ | H28: Finishing Process | I28: Cleaning,Last Inspection, Labeling & Application Buble Wrap | L28: 8 | S28: Quality Process Shift 2 (Daily) | U28: 1
G29: ▪ | H29: Packing Process | I29: Packing Product | L29: 2 | S29: Officer Quality Control (Daily) | U29: 1
H30: Additional Man Power | P30: ▪ | Q30: Maintenance | S30: Maintenace Shift 1 (Daily) | U30: 1
S31: Maintenance Shift 2 (Daily) | U31: 1
P32: ▪ | Q32: Engineering | S32: Engineering Field (Daily) | U32: 1
S33: Officer Engineering (Daily) | U33: 1
P34: ▪ | Q34: PPIC | S34: Officer PPIC (Daily) | U34: 1
Q35: Additional Man Power
D37: Total | G37: Direct Labor | L37: Qty | M37: Total | O37: ▪ Calculation Cost
G38: Station | I38: Process
G39: ▪ | H39: Leader | I39: Permanent Employed | L39: =SUM(U24) -> 4 | M39: =SUM(L39:L46) -> 80 | O39: 1. Man Power | R39: : | S39: =SUM(L40:L45)-3 -> 73 | T39: =218073+1000+13500 -> 232573 | U39: =S39*T39 -> 16977829 | X39: 2000000 | Z39: =S39*X39 -> 146000000 | AB39: =T39/16900 -> 13.761716 | AC39: =AB39*21 -> 288.99604
G40: ▪ | H40: Raw Material | I40: Daily Employed | L40: =SUM(U25) -> 1 | O40: 2. Leader QC & MTC | R40: : | S40: 2 | T40: =224610+1000+13500 -> 239110 | U40: =S40*T40 -> 478220 | X40: 4350000 | Z40: =S40*X40 -> 8700000
G41: ▪ | H41: Officer | I41: Daily Employed | L41: =SUM(U26,U29,U33,U34) -> 4 | O41: 3. Officer Engineering (Daily) | R41: : | S41: 1 | T41: =224610+10000+13500 -> 248110 | U41: =S41*T41 -> 248110 | X41: 4350000 | Z41: =S41*X41 -> 4350000
G42: ▪ | H42: Maintenance | I42: Daily Employed | L42: =SUM(U30:U31) -> 2 | O42: 4. Permanent Employed | R42: : | S42: =L39 -> 4 | T42: =224610+1000+13500 -> 239110 | U42: =S42*T42 -> 956440 | W42: + | X42: 4350000 | Z42: =S42*X42 -> 17400000 | AE42: +
G43: ▪ | H43: Quality | I43: Daily Employed | L43: =SUM(U27:U28) -> 2 | U43: =SUM(U39:V42) -> 18660599 | Z43: =SUM(Z39:Z42) -> 176450000 | AC43: =U43*10.5 -> 1.9593629e+08
G44: ▪ | H44: Engineering | I44: Daily Employed | L44: 1 | O44: ▪ Cost for Overtime (Saturday) | AC44: =AC43/16000 -> 12246.018
G45: ▪ | H45: Man Power | I45: Daily Employed | L45: =SUM(M8,V8,M24) -> 66 | O45: 1. Permanent Employed | R45: : | S45: 4 | T45: =(218073)*70% -> 152651.1 | U45: =S45*T45 -> 610604.4
H46: Additional Man Power | W46: +
...

Sheet Schedule Production (4)
D2: February 2026 | M2: Updated : | N2: 46091
D3: MASTER PLANNING SCHEDULE
E5: Idle : | F5: =I5-N5 -> 7 | H5: Normal Days : | I5: 20 | M5: Working Days : | N5: =COUNT(P7:AP7) -> 13 | P5: S | Q5: M | R5: T | S5: W | T5: T | U5: F | V5: S | W5: S | X5: M | Y5: T | Z5: W | AA5: T | AB5: F | AC5: S | AD5: S | AE5: M | AF5: T | AG5: W | AH5: T | AI5: F | AJ5: S | AK5: S | AL5: M | AM5: T | AN5: W | AO5: T | AP5: F | AQ5: S
B6: No | C6: No PO | D6: Customers | E6: Detailed Product | H6: Qty (Order) | I6: Production Process | O6: Total Plan | P6: 1 | Q6: 2 | R6: 3 | S6: 4 | T6: 5 | U6: 6 | V6: 7 | W6: 8 | X6: 9 | Y6: 10 | Z6: 11 | AA6: 12 | AB6: 13 | AC6: 14 | AD6: 15 | AE6: 16 | AF6: 17 | AG6: 18 | AH6: 19 | AI6: 20 | AJ6: 21 | AK6: 22 | AL6: 23 | AM6: 24 | AN6: 25 | AO6: 26 | AP6: 27 | AQ6: 28
E7: Type | F7: Label | G7: Wp | X7: 2 | Y7: 2 | Z7: 2 | AA7: 2 | AB7: 2 | AC7: 2 | AE7: 2 | AF7: 2 | AG7: 2 | AH7: 2 | AI7: 1 | AO7: 2 | AP7: 2 | AQ7: 2
B8: 1 | C8: 00609804 (No.6) | D8: VALTERRA | E8: 73907-F | F8: THERMOKING | G8: 35 | H8: 1000 | I8: Prepration - Cutting Laser Module | O8: =SUM(P8:AP8) -> 450 | U8: 150 | X8: 160 | Y8: 140
I9: Instalation Junction Box - Packaging Process | O9: =SUM(P9:AQ9) -> 460 | X9: 240 | Y9: 220
B10: 2 | C10: 00609684 (No.5) | D10: VALTERRA | E10: 82882-C | F10: NAVIGATOR | G10: 50 | H10: 1000 | I10: Prepration - Cutting Laser Module | O10: =SUM(P10:AP10) -> 1000 | Y10: 80 | Z10: 240 | AA10: 240 | AB10: 240 | AC10: 200
I11: Instalation Junction Box - Packaging Process | O11: =SUM(P11:AQ11) -> 960 | Y11: 60 | Z11: 240 | AA11: 240 | AB11: 240 | AC11: 180
B12: 4 | C12: 00609820 (Part 1) (No.8) | D12: VALTERRA | E12: 73907-F | F12: THERMOKING | G12: 35 | H12: 500 | I12: Prepration - Cutting Laser Module | O12: =SUM(P12:AQ12) -> 500 | AG12: 180 | AH12: 240 | AI12: 80
I13: Instalation Junction Box - Packaging Process | O13: =SUM(P13:AQ13) -> 320 | AG13: 60 | AH13: 140 | AI13: 120
B14: 5. | C14: 00609820 (Part 2) (No.8) | D14: VALTERRA | E14: 73907-F | F14: THERMOKING | G14: 35 | H14: 1500 | I14: Prepration - Cutting Laser Module | O14: =SUM(P14:AQ14) -> 0
I15: Instalation Junction Box - Packaging Process | O15: =SUM(P15:AQ15) -> 0
B16: 5 | C16: 00609880 | D16: VALTERRA | E16: 82882-C | F16: THERMOKING | G16: 50 | H16: 1000 | I16: Prepration - Cutting Laser Module | O16: =SUM(P16:AP16) -> 0
I17: Instalation Junction Box - Packaging Process | O17: =SUM(P17:AQ17) -> 0
I22: Prepration - Cutting Laser Module | O22: =SUM(O8,O10,O12,O14) -> 1950 | AA22: 35W (PO.9804) | AE22: 50W (PO.9684) | AI22: 35W (PO.9804 & 9820) | AN22: 35W (PO.9820)
I23: Instalation Junction Box - Packaging Process | O23: =SUM(O9,O11,O13,O15) -> 1740 | AB23: 450 PCS (US) | AF23: 540 pcs (IRE) | AI23: 10 + 320 PCS (US) | AO23: 180 PCS | AQ23: (US)
AI24: 50W (PO.9684)
D25: March 2026 | AJ25: 420 pcs | AL25: (IRE)
D26: MASTER PLANNING SCHEDULE
E28: Idle : | F28: =I28-N28 -> 0 | H28: Normal Days : | I28: 19 | M28: Working Days : | N28: =COUNT(P30:AT30) -> 19 | P28: S | Q28: M | R28: T | S28: W | T28: T | U28: F | V28: S | W28: S | X28: M | Y28: T | Z28: W | AA28: T | AB28: F | AC28: S | AD28: S | AE28: M | AF28: T | AG28: W | AH28: T | AI28: F | AJ28: S | AK28: S | AL28: M | AM28: T | AN28: W | AO28: T | AP28: F | AQ28: S | AR28: S | AS28: M | AT28: T
B29: No | C29: No PO | D29: Customers | E29: Detailed Product | H29: Qty (Order) | I29: Production Process | O29: Total Plan | P29: 1 | Q29: 2 | R29: 3 | S29: 4 | T29: 5 | U29: 6 | V29: 7 | W29: 8 | X29: 9 | Y29: 10 | Z29: 11 | AA29: 12 | AB29: 13 | AC29: 14 | AD29: 15 | AE29: 16 | AF29: 17 | AG29: 18 | AH29: 19 | AI29: 20 | AJ29: 21 | AK29: 22 | AL29: 23 | AM29: 24 | AN29: 25 | AO29: 26 | AP29: 27 | AQ29: 28 | AR29: 29 | AS29: 30 | AT29: 31
E30: Type | F30: Label | G30: Wp | T30: 1 | U30: 2 | V30: 2 | W30: 2 | X30: 2 | Y30: 2 | Z30: 2 | AA30: 2 | AB30: 2 | AC30: 2 | AD30: 2 | AE30: 2 | AF30: 2 | AN30: 2 | AO30: 2 | AP30: 2 | AQ30: 2 | AS30: 2 | AT30: 2
B31: 1 | C31: 00609684 (No.5) | D31: VALTERRA | E31: 82882-C | F31: NAVIGATOR | G31: 50 | H31: 1000 | I31: Prepration - Cutting Laser Module | O31: =SUM(P31:AP31) -> 0
I32: Instalation Junction Box - Packaging Process | O32: =SUM(P32:AQ32) -> 40 | T32: 40
B33: 2 | C33: 00609820 (Part 1) (No.8) | D33: VALTERRA | E33: 73907-F | F33: THERMOKING | G33: 35 | H33: 500 | I33: Prepration - Cutting Laser Module | O33: =SUM(P33:AT33) -> 0
I34: Instalation Junction Box - Packaging Process | O34: =SUM(P34:AT34) -> 180 | T34: 180
B35: 3 | C35: 00609820 (Part 2) (No.8) | D35: VALTERRA | E35: 73907-F | F35: THERMOKING | G35: 35 | H35: 1500 | I35: Prepration - Cutting Laser Module | O35: =SUM(P35:AT35) -> 1500 | U35: 160 | V35: 220 | W35: 280 | X35: 280 | Y35: 80 | Z35: 280 | AA35: 200
I36: Instalation Junction Box - Packaging Process | O36: =SUM(P36:AT36) -> 1500 | U36: 80 | V36: 140 | W36: 240 | X36: 80 | AC36: 600 | AD36: 300 | AE36: 60
B37: 4 | C37: 00609784 (No.7) | D37: VALTERRA | E37: 82882-C | F37: NAVIGATOR | G37: 50 | H37: 1000 | I37: Prepration - Cutting Laser Module | O37: =SUM(P37:AT37) -> 1000 | Y37: 140 | AB37: 240 | AC37: 120 | AN37: 120 | AO37: 180 | AP37: 200
I38: Instalation Junction Box - Packaging Process | O38: =SUM(P38:AT38) -> 1000 | Y38: 140 | AD38: 360 | AN38: 80 | AO38: 180 | AP38: 240
B39: 5 | C39: 00609820 (Part 3) (No.8) | D39: VALTERRA | E39: 73907 - F | F39: THERMOKING | G39: 35 | H39: 2000 | I39: Prepration - Cutting Laser Module | O39: =SUM(P39:AT39) -> 840 | AQ39: 280 | AS39: 280 | AT39: 280
I40: Instalation Junction Box - Packaging Process | O40: =SUM(P40:AT40) -> 840 | AQ40: 280 | AS40: 280 | AT40: 280
I45: Prepration - Cutting Laser Module | O45: =SUM(O31,O33,O35,O37) -> 2500 | V45: 35W (PO.9820) | Y45: 35W (PO.9820) | AB45: 50W (PO.9684 & 9784) | AF45: 35W PO.9820 | AP45: 35W (PO.9820) | AS45: 35W (PO.9820)
I46: Instalation Junction Box - Packaging Process | O46: =SUM(O32,O34,O36,O38) -> 2720 | V46: 180 pcs | Y46: 540 PCS | AB46: 40 + 140 PCS | AF46: 900 pcs | AP46: 540 | AS46: =1460-540 -> 920
AF47: 50W PO.9784
D48: April 2026 | O48: =O39+O54 -> 2000 | AF48: 360 pcs
D49: MASTER PLANNING SCHEDULE | O49: =O40+O55 -> 2000
E51: Idle : | F51: =I51-N51 -> -4 | H51: Normal Days : | I51: 19 | M51: Working Days : | N51: =COUNT(P53:AS53) -> 23 | P51: W | Q51: T | R51: F | S51: S | T51: S | U51: M | V51: T | W51: W | X51: T | Y51: F | Z51: S | AA51: S | AB51: M | AC51: T | AD51: W | AE51: T | AF51: F | AG51: S | AH51: S | AI51: M | AJ51: T | AK51: W | AL51: T | AM51: F | AN51: S | AO51: S | AP51: M | AQ51: T | AR51: W | AS51: T
B52: No | C52: No PO | D52: Customers | E52: Detailed Product | H52: Qty (Order) | I52: Production Process | O52: Total Plan | P52: 1 | Q52: 2 | R52: 3 | S52: 4 | T52: 5 | U52: 6 | V52: 7 | W52: 8 | X52: 9 | Y52: 10 | Z52: 11 | AA52: 12 | AB52: 13 | AC52: 14 | AD52: 15 | AE52: 16 | AF52: 17 | AG52: 18 | AH52: 19 | AI52: 20 | AJ52: 21 | AK52: 22 | AL52: 23 | AM52: 24 | AN52: 25 | AO52: 26 | AP52: 27 | AQ52: 28 | AR52: 29 | AS52: 30
...

Sheet Planning Man Power
E2: MONITORING PLANNING
E3: MAN POWER | H3: 26 - 28 FEBRUARY 2026
B5: Shift 1 | E5: Direct Labor | J5: Qty | K5: Total | M5: Man Power Name | U5: Total | W5: Prepared by,
E6: Station | G6: Process | M6: 1 | N6: 2 | O6: 3 | P6: 4 | Q6: 5 | R6: 6 | S6: 7 | T6: 8
E8: ▪ | F8: Preparation | G8: Sortr Cell & Cutting Cell | J8: 2 | K8: =SUM(J8:J19) -> 25 | U8: =COUNTA(M8:T8) -> 0
G9: Cutting Eva & Backsheet | J9: 2 | U9: =COUNTA(M9:T9) -> 0
G10: Cutting Ribbon & Busbar | J10: 1 | U10: =COUNTA(M10:T10) -> 0
G11: Assembling Junction Box | J11: 2 | U11: =COUNTA(M11:T11) -> 0
E12: ▪ | F12: Soldering | G12: Series Soldering | J12: 5 | U12: =COUNTA(M12:T12) -> 0
G13: Lay - Up (Assymbling Module) | J13: 6 | U13: =COUNTA(M13:T13) -> 0
E14: ▪ | F14: Inspection Quality | G14: EL - Test | J14: 1 | U14: =COUNTA(M14:T14) -> 0
G15: Visual Check | J15: 2 | U15: =COUNTA(M15:T15) -> 0
E16: ▪ | F16: Laminating | G16: Laminated Process | J16: 2 | U16: =COUNTA(M16:T16) -> 0
G17: Application Protection Film | U17: =COUNTA(M17:T17) -> 0
E18: ▪ | F18: Assymbling | G18: Cutting Module & Instalasi Grommet | J18: 2 | U18: =COUNTA(M18:T18) -> 0 | W18: Checking by,
F19: Additional Man Power | U19: =COUNTA(M19:T19) -> 0
B21: Non Shift | E21: Direct Labor | J21: Qty | K21: Total | M21: Man Power Name | U21: Total
E22: Station | G22: Process | M22: 1 | N22: 2 | O22: 3 | P22: 4 | Q22: 5 | R22: 6 | S22: 7 | T22: 8
E24: ▪ | F24: Assymbling | G24: Instalasi Junction Box | J24: 2 | K24: =SUM(J24:J30) -> 16 | U24: =COUNTA(M24:T24) -> 0
E25: ▪ | F25: Inspection Quality | G25: Test IV (Sunsimulator) | J25: 1 | U25: =COUNTA(M25:T25) -> 0
G26: EL - Test | J26: 1 | U26: =COUNTA(M26:T26) -> 0
E27: ▪ | F27: Coating Process | G27: Application Potting gell | J27: 2 | U27: =COUNTA(M27:T27) -> 0
E28: ▪ | F28: Finishing Process | G28: Cleaning,Last Inspection, Labeling & Application Buble Wrap | J28: 8 | U28: =COUNTA(M28:T28) -> 0
E29: ▪ | F29: Packing Process | G29: Packing Product | J29: 2 | U29: =COUNTA(M29:T29) -> 0
F30: Additional Man Power | U30: =COUNTA(M30:T30) -> 0
W31: Approved by
B32: Shift 2 | E32: Direct Labor | J32: Qty | K32: Total | M32: Man Power Name | U32: Total
E33: Station | G33: Process | M33: 1 | N33: 2 | O33: 3 | P33: 4 | Q33: 5 | R33: 6 | S33: 7 | T33: 8
E35: ▪ | F35: Preparation | G35: Sortr Cell & Cutting Cell | J35: 2 | K35: =SUM(J35:J46) -> 25 | U35: =COUNTA(M35:T35) -> 0
G36: Cutting Eva & Backsheet | J36: 2 | U36: =COUNTA(M36:T36) -> 0
G37: Cutting Ribbon & Busbar | J37: 1 | U37: =COUNTA(M37:T37) -> 0
G38: Assembling Junction Box | J38: 2 | U38: =COUNTA(M38:T38) -> 0
E39: ▪ | F39: Soldering | G39: Series Soldering | J39: 5 | U39: =COUNTA(M39:T39) -> 0
G40: Lay - Up (Assymbling Module) | J40: 6 | U40: =COUNTA(M40:T40) -> 0
E41: ▪ | F41: Inspection Quality | G41: EL - Test | J41: 1 | U41: =COUNTA(M41:T41) -> 0
G42: Visual Check | J42: 2 | U42: =COUNTA(M42:T42) -> 0
E43: ▪ | F43: Laminating | G43: Laminated Process | J43: 2 | U43: =COUNTA(M43:T43) -> 0
G44: Application Protection Film | U44: =COUNTA(M44:T44) -> 0 | W44: Approved by
E45: ▪ | F45: Assymbling | G45: Cutting Module & Instalasi Grommet | J45: 2 | U45: =COUNTA(M45:T45) -> 0
F46: Additional Man Power | U46: =COUNTA(M46:T46) -> 0
...
